--- catch(tag) {|tag| .... }

    ブロックを実行してその値を返します。ブロックの実行中に
    tag と同じ名前の throw が行われた
    場合は、その throw の第二引数を戻り値とします。

    例えば以下のコードを実行すると some_process は
    呼び出されず、また catch の戻り値は 10 ではなく 25 に
    なります。

      ret = catch(:exit) {
         throw :exit, 25
         some_process()
         10
      }
      p ret   #=> 25

    ネストしたループは break によって一気に抜
    けることはできません。
    このような場合、catch や 例外 [制御構造/begin] を使用します。

      catch(:loop1) {
        for i in 1..2
          for j in 1..2
            throw :loop1, j
          end
        end
      }

